[2023-06-30T19:28:11.275+0000] {taskinstance.py:1103} INFO - Dependencies all met for dep_context=non-requeueable deps ti=<TaskInstance: dag_with_python_deps.get_sklearn manual__2023-06-30T19:26:09.484854+00:00 [queued]>
[2023-06-30T19:28:11.281+0000] {taskinstance.py:1103} INFO - Dependencies all met for dep_context=requeueable deps ti=<TaskInstance: dag_with_python_deps.get_sklearn manual__2023-06-30T19:26:09.484854+00:00 [queued]>
[2023-06-30T19:28:11.281+0000] {taskinstance.py:1308} INFO - Starting attempt 2 of 6
[2023-06-30T19:28:11.291+0000] {taskinstance.py:1327} INFO - Executing <Task(PythonOperator): get_sklearn> on 2023-06-30 19:26:09.484854+00:00
[2023-06-30T19:28:11.295+0000] {standard_task_runner.py:57} INFO - Started process 1240 to run task
[2023-06-30T19:28:11.297+0000] {standard_task_runner.py:84} INFO - Running: ['***', 'tasks', 'run', 'dag_with_python_deps', 'get_sklearn', 'manual__2023-06-30T19:26:09.484854+00:00', '--job-id', '87', '--raw', '--subdir', 'DAGS_FOLDER/dag_with_python_deps.py', '--cfg-path', '/tmp/tmp3x6v8qmj']
[2023-06-30T19:28:11.298+0000] {standard_task_runner.py:85} INFO - Job 87: Subtask get_sklearn
[2023-06-30T19:28:11.328+0000] {task_command.py:410} INFO - Running <TaskInstance: dag_with_python_deps.get_sklearn manual__2023-06-30T19:26:09.484854+00:00 [running]> on host 40ec38a36dc7
[2023-06-30T19:28:11.383+0000] {taskinstance.py:1547} INFO - Exporting env vars: AIRFLOW_CTX_DAG_OWNER='stare' AIRFLOW_CTX_DAG_ID='dag_with_python_deps' AIRFLOW_CTX_TASK_ID='get_sklearn' AIRFLOW_CTX_EXECUTION_DATE='2023-06-30T19:26:09.484854+00:00' AIRFLOW_CTX_TRY_NUMBER='2' AIRFLOW_CTX_DAG_RUN_ID='manual__2023-06-30T19:26:09.484854+00:00'
[2023-06-30T19:28:11.384+0000] {taskinstance.py:1824} ERROR - Task failed with exception
Traceback (most recent call last):
  File "/home/airflow/.local/lib/python3.7/site-packages/airflow/operators/python.py", line 181, in execute
    return_value = self.execute_callable()
  File "/home/airflow/.local/lib/python3.7/site-packages/airflow/operators/python.py", line 198, in execute_callable
    return self.python_callable(*self.op_args, **self.op_kwargs)
  File "/opt/airflow/dags/dag_with_python_deps.py", line 13, in get_sklearn
    import sklearn
ModuleNotFoundError: No module named 'sklearn'
[2023-06-30T19:28:11.389+0000] {taskinstance.py:1350} INFO - Marking task as UP_FOR_RETRY. dag_id=dag_with_python_deps, task_id=get_sklearn, execution_date=20230630T192609, start_date=20230630T192811, end_date=20230630T192811
[2023-06-30T19:28:11.397+0000] {standard_task_runner.py:109} ERROR - Failed to execute job 87 for task get_sklearn (No module named 'sklearn'; 1240)
[2023-06-30T19:28:11.428+0000] {local_task_job_runner.py:225} INFO - Task exited with return code 1
[2023-06-30T19:28:11.441+0000] {taskinstance.py:2653} INFO - 0 downstream tasks scheduled from follow-on schedule check
