[2023-07-01T23:38:19.144+0000] {taskinstance.py:1103} INFO - Dependencies all met for dep_context=non-requeueable deps ti=<TaskInstance: dag_python_deps_NEW6.print_the_context manual__2023-07-01T23:38:18.537004+00:00 [queued]>
[2023-07-01T23:38:19.156+0000] {taskinstance.py:1103} INFO - Dependencies all met for dep_context=requeueable deps ti=<TaskInstance: dag_python_deps_NEW6.print_the_context manual__2023-07-01T23:38:18.537004+00:00 [queued]>
[2023-07-01T23:38:19.157+0000] {taskinstance.py:1308} INFO - Starting attempt 1 of 6
[2023-07-01T23:38:19.170+0000] {taskinstance.py:1327} INFO - Executing <Task(_PythonDecoratedOperator): print_the_context> on 2023-07-01 23:38:18.537004+00:00
[2023-07-01T23:38:19.175+0000] {standard_task_runner.py:57} INFO - Started process 11013 to run task
[2023-07-01T23:38:19.177+0000] {standard_task_runner.py:84} INFO - Running: ['***', 'tasks', 'run', 'dag_python_deps_NEW6', 'print_the_context', 'manual__2023-07-01T23:38:18.537004+00:00', '--job-id', '245', '--raw', '--subdir', 'DAGS_FOLDER/dag_with_python_deps.py', '--cfg-path', '/tmp/tmpzg_vu722']
[2023-07-01T23:38:19.177+0000] {standard_task_runner.py:85} INFO - Job 245: Subtask print_the_context
[2023-07-01T23:38:19.220+0000] {task_command.py:410} INFO - Running <TaskInstance: dag_python_deps_NEW6.print_the_context manual__2023-07-01T23:38:18.537004+00:00 [running]> on host 111d544596aa
[2023-07-01T23:38:19.294+0000] {taskinstance.py:1547} INFO - Exporting env vars: AIRFLOW_CTX_DAG_OWNER='stare' AIRFLOW_CTX_DAG_ID='dag_python_deps_NEW6' AIRFLOW_CTX_TASK_ID='print_the_context' AIRFLOW_CTX_EXECUTION_DATE='2023-07-01T23:38:18.537004+00:00' AIRFLOW_CTX_TRY_NUMBER='1' AIRFLOW_CTX_DAG_RUN_ID='manual__2023-07-01T23:38:18.537004+00:00'
[2023-07-01T23:38:19.295+0000] {taskinstance.py:1824} ERROR - Task failed with exception
Traceback (most recent call last):
  File "/home/airflow/.local/lib/python3.7/site-packages/airflow/decorators/base.py", line 220, in execute
    return_value = super().execute(context)
  File "/home/airflow/.local/lib/python3.7/site-packages/airflow/operators/python.py", line 181, in execute
    return_value = self.execute_callable()
  File "/home/airflow/.local/lib/python3.7/site-packages/airflow/operators/python.py", line 198, in execute_callable
    return self.python_callable(*self.op_args, **self.op_kwargs)
  File "/opt/airflow/dags/dag_with_python_deps.py", line 26, in print_context
    pprint(kwargs)
UnboundLocalError: local variable 'pprint' referenced before assignment
[2023-07-01T23:38:19.302+0000] {taskinstance.py:1350} INFO - Marking task as UP_FOR_RETRY. dag_id=dag_python_deps_NEW6, task_id=print_the_context, execution_date=20230701T233818, start_date=20230701T233819, end_date=20230701T233819
[2023-07-01T23:38:19.310+0000] {standard_task_runner.py:109} ERROR - Failed to execute job 245 for task print_the_context (local variable 'pprint' referenced before assignment; 11013)
[2023-07-01T23:38:19.349+0000] {local_task_job_runner.py:225} INFO - Task exited with return code 1
[2023-07-01T23:38:19.364+0000] {taskinstance.py:2653} INFO - 0 downstream tasks scheduled from follow-on schedule check
