[2023-07-07T16:27:02.105+0000] {taskinstance.py:1103} INFO - Dependencies all met for dep_context=non-requeueable deps ti=<TaskInstance: test_imports_v8.get_data manual__2023-07-07T16:27:01.570283+00:00 [queued]>
[2023-07-07T16:27:02.112+0000] {taskinstance.py:1103} INFO - Dependencies all met for dep_context=requeueable deps ti=<TaskInstance: test_imports_v8.get_data manual__2023-07-07T16:27:01.570283+00:00 [queued]>
[2023-07-07T16:27:02.112+0000] {taskinstance.py:1308} INFO - Starting attempt 1 of 1
[2023-07-07T16:27:02.123+0000] {taskinstance.py:1327} INFO - Executing <Task(_PythonDecoratedOperator): get_data> on 2023-07-07 16:27:01.570283+00:00
[2023-07-07T16:27:02.129+0000] {standard_task_runner.py:57} INFO - Started process 244 to run task
[2023-07-07T16:27:02.131+0000] {standard_task_runner.py:84} INFO - Running: ['***', 'tasks', 'run', 'test_imports_v8', 'get_data', 'manual__2023-07-07T16:27:01.570283+00:00', '--job-id', '80', '--raw', '--subdir', 'DAGS_FOLDER/scrap_data.py', '--cfg-path', '/tmp/tmp7_j3x91n']
[2023-07-07T16:27:02.131+0000] {standard_task_runner.py:85} INFO - Job 80: Subtask get_data
[2023-07-07T16:27:02.163+0000] {task_command.py:410} INFO - Running <TaskInstance: test_imports_v8.get_data manual__2023-07-07T16:27:01.570283+00:00 [running]> on host d409bdcb9602
[2023-07-07T16:27:02.230+0000] {taskinstance.py:1547} INFO - Exporting env vars: AIRFLOW_CTX_DAG_OWNER='***' AIRFLOW_CTX_DAG_ID='test_imports_v8' AIRFLOW_CTX_TASK_ID='get_data' AIRFLOW_CTX_EXECUTION_DATE='2023-07-07T16:27:01.570283+00:00' AIRFLOW_CTX_TRY_NUMBER='1' AIRFLOW_CTX_DAG_RUN_ID='manual__2023-07-07T16:27:01.570283+00:00'
[2023-07-07T16:27:02.231+0000] {logging_mixin.py:149} INFO - ['/home/***/.local/bin', '/usr/local/lib/python37.zip', '/usr/local/lib/python3.7', '/usr/local/lib/python3.7/lib-dynload', '/home/***/.local/lib/python3.7/site-packages', '/usr/local/lib/python3.7/site-packages', '/opt/***/dags', '/opt/***/config', '/opt/***/plugins']
[2023-07-07T16:27:02.231+0000] {taskinstance.py:1824} ERROR - Task failed with exception
Traceback (most recent call last):
  File "/home/airflow/.local/lib/python3.7/site-packages/airflow/decorators/base.py", line 220, in execute
    return_value = super().execute(context)
  File "/home/airflow/.local/lib/python3.7/site-packages/airflow/operators/python.py", line 181, in execute
    return_value = self.execute_callable()
  File "/home/airflow/.local/lib/python3.7/site-packages/airflow/operators/python.py", line 198, in execute_callable
    return self.python_callable(*self.op_args, **self.op_kwargs)
  File "/opt/airflow/dags/scrap_data.py", line 25, in get_data
    import selenium
ModuleNotFoundError: No module named 'selenium'
[2023-07-07T16:27:02.237+0000] {taskinstance.py:1350} INFO - Marking task as FAILED. dag_id=test_imports_v8, task_id=get_data, execution_date=20230707T162701, start_date=20230707T162702, end_date=20230707T162702
[2023-07-07T16:27:02.245+0000] {standard_task_runner.py:109} ERROR - Failed to execute job 80 for task get_data (No module named 'selenium'; 244)
[2023-07-07T16:27:02.263+0000] {local_task_job_runner.py:225} INFO - Task exited with return code 1
[2023-07-07T16:27:02.276+0000] {taskinstance.py:2653} INFO - 0 downstream tasks scheduled from follow-on schedule check
