[2023-07-01T00:26:16.663+0000] {taskinstance.py:1103} INFO - Dependencies all met for dep_context=non-requeueable deps ti=<TaskInstance: dag_with_python_deps.get_sklearn manual__2023-07-01T00:20:12.812488+00:00 [queued]>
[2023-07-01T00:26:16.669+0000] {taskinstance.py:1103} INFO - Dependencies all met for dep_context=requeueable deps ti=<TaskInstance: dag_with_python_deps.get_sklearn manual__2023-07-01T00:20:12.812488+00:00 [queued]>
[2023-07-01T00:26:16.669+0000] {taskinstance.py:1308} INFO - Starting attempt 4 of 6
[2023-07-01T00:26:16.679+0000] {taskinstance.py:1327} INFO - Executing <Task(PythonOperator): get_sklearn> on 2023-07-01 00:20:12.812488+00:00
[2023-07-01T00:26:16.684+0000] {standard_task_runner.py:57} INFO - Started process 469 to run task
[2023-07-01T00:26:16.686+0000] {standard_task_runner.py:84} INFO - Running: ['***', 'tasks', 'run', 'dag_with_python_deps', 'get_sklearn', 'manual__2023-07-01T00:20:12.812488+00:00', '--job-id', '123', '--raw', '--subdir', 'DAGS_FOLDER/dag_with_python_deps.py', '--cfg-path', '/tmp/tmpq_u7rgvw']
[2023-07-01T00:26:16.686+0000] {standard_task_runner.py:85} INFO - Job 123: Subtask get_sklearn
[2023-07-01T00:26:16.718+0000] {task_command.py:410} INFO - Running <TaskInstance: dag_with_python_deps.get_sklearn manual__2023-07-01T00:20:12.812488+00:00 [running]> on host 111d544596aa
[2023-07-01T00:26:16.774+0000] {taskinstance.py:1547} INFO - Exporting env vars: AIRFLOW_CTX_DAG_OWNER='stare' AIRFLOW_CTX_DAG_ID='dag_with_python_deps' AIRFLOW_CTX_TASK_ID='get_sklearn' AIRFLOW_CTX_EXECUTION_DATE='2023-07-01T00:20:12.812488+00:00' AIRFLOW_CTX_TRY_NUMBER='4' AIRFLOW_CTX_DAG_RUN_ID='manual__2023-07-01T00:20:12.812488+00:00'
[2023-07-01T00:26:16.774+0000] {taskinstance.py:1824} ERROR - Task failed with exception
Traceback (most recent call last):
  File "/home/airflow/.local/lib/python3.7/site-packages/airflow/operators/python.py", line 181, in execute
    return_value = self.execute_callable()
  File "/home/airflow/.local/lib/python3.7/site-packages/airflow/operators/python.py", line 198, in execute_callable
    return self.python_callable(*self.op_args, **self.op_kwargs)
  File "/opt/airflow/dags/dag_with_python_deps.py", line 13, in get_sklearn
    import sklearn
ModuleNotFoundError: No module named 'sklearn'
[2023-07-01T00:26:16.780+0000] {taskinstance.py:1350} INFO - Marking task as UP_FOR_RETRY. dag_id=dag_with_python_deps, task_id=get_sklearn, execution_date=20230701T002012, start_date=20230701T002616, end_date=20230701T002616
[2023-07-01T00:26:16.787+0000] {standard_task_runner.py:109} ERROR - Failed to execute job 123 for task get_sklearn (No module named 'sklearn'; 469)
[2023-07-01T00:26:16.818+0000] {local_task_job_runner.py:225} INFO - Task exited with return code 1
[2023-07-01T00:26:16.832+0000] {taskinstance.py:2653} INFO - 0 downstream tasks scheduled from follow-on schedule check
