[2023-06-29T21:36:04.883+0000] {taskinstance.py:1103} INFO - Dependencies all met for dep_context=non-requeueable deps ti=<TaskInstance: dag_python_operador_03.greet manual__2023-06-29T21:36:02.557517+00:00 [queued]>
[2023-06-29T21:36:04.890+0000] {taskinstance.py:1103} INFO - Dependencies all met for dep_context=requeueable deps ti=<TaskInstance: dag_python_operador_03.greet manual__2023-06-29T21:36:02.557517+00:00 [queued]>
[2023-06-29T21:36:04.890+0000] {taskinstance.py:1308} INFO - Starting attempt 1 of 6
[2023-06-29T21:36:04.900+0000] {taskinstance.py:1327} INFO - Executing <Task(PythonOperator): greet> on 2023-06-29 21:36:02.557517+00:00
[2023-06-29T21:36:04.904+0000] {standard_task_runner.py:57} INFO - Started process 1847 to run task
[2023-06-29T21:36:04.906+0000] {standard_task_runner.py:84} INFO - Running: ['***', 'tasks', 'run', 'dag_python_operador_03', 'greet', 'manual__2023-06-29T21:36:02.557517+00:00', '--job-id', '21', '--raw', '--subdir', 'DAGS_FOLDER/create_dag_with_python_operator.py', '--cfg-path', '/tmp/tmpftt7qk1w']
[2023-06-29T21:36:04.906+0000] {standard_task_runner.py:85} INFO - Job 21: Subtask greet
[2023-06-29T21:36:04.936+0000] {task_command.py:410} INFO - Running <TaskInstance: dag_python_operador_03.greet manual__2023-06-29T21:36:02.557517+00:00 [running]> on host 3a20bfb037db
[2023-06-29T21:36:04.991+0000] {taskinstance.py:1547} INFO - Exporting env vars: AIRFLOW_CTX_DAG_OWNER='stare' AIRFLOW_CTX_DAG_ID='dag_python_operador_03' AIRFLOW_CTX_TASK_ID='greet' AIRFLOW_CTX_EXECUTION_DATE='2023-06-29T21:36:02.557517+00:00' AIRFLOW_CTX_TRY_NUMBER='1' AIRFLOW_CTX_DAG_RUN_ID='manual__2023-06-29T21:36:02.557517+00:00'
[2023-06-29T21:36:04.992+0000] {taskinstance.py:1824} ERROR - Task failed with exception
Traceback (most recent call last):
  File "/home/airflow/.local/lib/python3.7/site-packages/airflow/operators/python.py", line 181, in execute
    return_value = self.execute_callable()
  File "/home/airflow/.local/lib/python3.7/site-packages/airflow/operators/python.py", line 198, in execute_callable
    return self.python_callable(*self.op_args, **self.op_kwargs)
  File "/opt/airflow/dags/create_dag_with_python_operator.py", line 13, in greet
    name = ti.xcoms_pull(task_ids='get_name')
AttributeError: 'TaskInstance' object has no attribute 'xcoms_pull'
[2023-06-29T21:36:04.997+0000] {taskinstance.py:1350} INFO - Marking task as UP_FOR_RETRY. dag_id=dag_python_operador_03, task_id=greet, execution_date=20230629T213602, start_date=20230629T213604, end_date=20230629T213604
[2023-06-29T21:36:05.003+0000] {standard_task_runner.py:109} ERROR - Failed to execute job 21 for task greet ('TaskInstance' object has no attribute 'xcoms_pull'; 1847)
[2023-06-29T21:36:05.038+0000] {local_task_job_runner.py:225} INFO - Task exited with return code 1
[2023-06-29T21:36:05.057+0000] {taskinstance.py:2653} INFO - 0 downstream tasks scheduled from follow-on schedule check
