[2023-07-01T03:46:12.140+0000] {taskinstance.py:1103} INFO - Dependencies all met for dep_context=non-requeueable deps ti=<TaskInstance: dag_with_python_deps.get_sklearn manual__2023-07-01T03:40:08.463228+00:00 [queued]>
[2023-07-01T03:46:12.146+0000] {taskinstance.py:1103} INFO - Dependencies all met for dep_context=requeueable deps ti=<TaskInstance: dag_with_python_deps.get_sklearn manual__2023-07-01T03:40:08.463228+00:00 [queued]>
[2023-07-01T03:46:12.146+0000] {taskinstance.py:1308} INFO - Starting attempt 4 of 6
[2023-07-01T03:46:12.156+0000] {taskinstance.py:1327} INFO - Executing <Task(PythonOperator): get_sklearn> on 2023-07-01 03:40:08.463228+00:00
[2023-07-01T03:46:12.160+0000] {standard_task_runner.py:57} INFO - Started process 3953 to run task
[2023-07-01T03:46:12.162+0000] {standard_task_runner.py:84} INFO - Running: ['***', 'tasks', 'run', 'dag_with_python_deps', 'get_sklearn', 'manual__2023-07-01T03:40:08.463228+00:00', '--job-id', '140', '--raw', '--subdir', 'DAGS_FOLDER/dag_with_python_deps.py', '--cfg-path', '/tmp/tmp24l6w_py']
[2023-07-01T03:46:12.162+0000] {standard_task_runner.py:85} INFO - Job 140: Subtask get_sklearn
[2023-07-01T03:46:12.193+0000] {task_command.py:410} INFO - Running <TaskInstance: dag_with_python_deps.get_sklearn manual__2023-07-01T03:40:08.463228+00:00 [running]> on host 111d544596aa
[2023-07-01T03:46:12.253+0000] {taskinstance.py:1547} INFO - Exporting env vars: AIRFLOW_CTX_DAG_OWNER='stare' AIRFLOW_CTX_DAG_ID='dag_with_python_deps' AIRFLOW_CTX_TASK_ID='get_sklearn' AIRFLOW_CTX_EXECUTION_DATE='2023-07-01T03:40:08.463228+00:00' AIRFLOW_CTX_TRY_NUMBER='4' AIRFLOW_CTX_DAG_RUN_ID='manual__2023-07-01T03:40:08.463228+00:00'
[2023-07-01T03:46:12.254+0000] {taskinstance.py:1824} ERROR - Task failed with exception
Traceback (most recent call last):
  File "/home/airflow/.local/lib/python3.7/site-packages/airflow/operators/python.py", line 181, in execute
    return_value = self.execute_callable()
  File "/home/airflow/.local/lib/python3.7/site-packages/airflow/operators/python.py", line 198, in execute_callable
    return self.python_callable(*self.op_args, **self.op_kwargs)
  File "/opt/airflow/dags/dag_with_python_deps.py", line 13, in get_sklearn
    import sklearn
ModuleNotFoundError: No module named 'sklearn'
[2023-07-01T03:46:12.259+0000] {taskinstance.py:1350} INFO - Marking task as UP_FOR_RETRY. dag_id=dag_with_python_deps, task_id=get_sklearn, execution_date=20230701T034008, start_date=20230701T034612, end_date=20230701T034612
[2023-07-01T03:46:12.267+0000] {standard_task_runner.py:109} ERROR - Failed to execute job 140 for task get_sklearn (No module named 'sklearn'; 3953)
[2023-07-01T03:46:12.293+0000] {local_task_job_runner.py:225} INFO - Task exited with return code 1
[2023-07-01T03:46:12.307+0000] {taskinstance.py:2653} INFO - 0 downstream tasks scheduled from follow-on schedule check
