[2023-07-01T03:56:34.786+0000] {taskinstance.py:1103} INFO - Dependencies all met for dep_context=non-requeueable deps ti=<TaskInstance: dag_with_python_deps.get_sklearn manual__2023-07-01T03:46:29.228280+00:00 [queued]>
[2023-07-01T03:56:34.793+0000] {taskinstance.py:1103} INFO - Dependencies all met for dep_context=requeueable deps ti=<TaskInstance: dag_with_python_deps.get_sklearn manual__2023-07-01T03:46:29.228280+00:00 [queued]>
[2023-07-01T03:56:34.793+0000] {taskinstance.py:1308} INFO - Starting attempt 6 of 6
[2023-07-01T03:56:34.807+0000] {taskinstance.py:1327} INFO - Executing <Task(PythonOperator): get_sklearn> on 2023-07-01 03:46:29.228280+00:00
[2023-07-01T03:56:34.813+0000] {standard_task_runner.py:57} INFO - Started process 4155 to run task
[2023-07-01T03:56:34.814+0000] {standard_task_runner.py:84} INFO - Running: ['***', 'tasks', 'run', 'dag_with_python_deps', 'get_sklearn', 'manual__2023-07-01T03:46:29.228280+00:00', '--job-id', '151', '--raw', '--subdir', 'DAGS_FOLDER/dag_with_python_deps.py', '--cfg-path', '/tmp/tmp2c863z1j']
[2023-07-01T03:56:34.815+0000] {standard_task_runner.py:85} INFO - Job 151: Subtask get_sklearn
[2023-07-01T03:56:34.852+0000] {task_command.py:410} INFO - Running <TaskInstance: dag_with_python_deps.get_sklearn manual__2023-07-01T03:46:29.228280+00:00 [running]> on host 111d544596aa
[2023-07-01T03:56:34.915+0000] {taskinstance.py:1547} INFO - Exporting env vars: AIRFLOW_CTX_DAG_OWNER='stare' AIRFLOW_CTX_DAG_ID='dag_with_python_deps' AIRFLOW_CTX_TASK_ID='get_sklearn' AIRFLOW_CTX_EXECUTION_DATE='2023-07-01T03:46:29.228280+00:00' AIRFLOW_CTX_TRY_NUMBER='6' AIRFLOW_CTX_DAG_RUN_ID='manual__2023-07-01T03:46:29.228280+00:00'
[2023-07-01T03:56:34.916+0000] {taskinstance.py:1824} ERROR - Task failed with exception
Traceback (most recent call last):
  File "/home/airflow/.local/lib/python3.7/site-packages/airflow/operators/python.py", line 181, in execute
    return_value = self.execute_callable()
  File "/home/airflow/.local/lib/python3.7/site-packages/airflow/operators/python.py", line 198, in execute_callable
    return self.python_callable(*self.op_args, **self.op_kwargs)
  File "/opt/airflow/dags/dag_with_python_deps.py", line 13, in get_sklearn
    import sklearn
ModuleNotFoundError: No module named 'sklearn'
[2023-07-01T03:56:34.922+0000] {taskinstance.py:1350} INFO - Marking task as FAILED. dag_id=dag_with_python_deps, task_id=get_sklearn, execution_date=20230701T034629, start_date=20230701T035634, end_date=20230701T035634
[2023-07-01T03:56:34.931+0000] {standard_task_runner.py:109} ERROR - Failed to execute job 151 for task get_sklearn (No module named 'sklearn'; 4155)
[2023-07-01T03:56:34.947+0000] {local_task_job_runner.py:225} INFO - Task exited with return code 1
[2023-07-01T03:56:34.961+0000] {taskinstance.py:2653} INFO - 0 downstream tasks scheduled from follow-on schedule check
