[2023-06-29T21:36:59.787+0000] {taskinstance.py:1103} INFO - Dependencies all met for dep_context=non-requeueable deps ti=<TaskInstance: dag_python_operador_03.greet manual__2023-06-29T21:36:58.120413+00:00 [queued]>
[2023-06-29T21:36:59.794+0000] {taskinstance.py:1103} INFO - Dependencies all met for dep_context=requeueable deps ti=<TaskInstance: dag_python_operador_03.greet manual__2023-06-29T21:36:58.120413+00:00 [queued]>
[2023-06-29T21:36:59.794+0000] {taskinstance.py:1308} INFO - Starting attempt 1 of 6
[2023-06-29T21:36:59.806+0000] {taskinstance.py:1327} INFO - Executing <Task(PythonOperator): greet> on 2023-06-29 21:36:58.120413+00:00
[2023-06-29T21:36:59.810+0000] {standard_task_runner.py:57} INFO - Started process 1860 to run task
[2023-06-29T21:36:59.813+0000] {standard_task_runner.py:84} INFO - Running: ['***', 'tasks', 'run', 'dag_python_operador_03', 'greet', 'manual__2023-06-29T21:36:58.120413+00:00', '--job-id', '23', '--raw', '--subdir', 'DAGS_FOLDER/create_dag_with_python_operator.py', '--cfg-path', '/tmp/tmpvy1w4h14']
[2023-06-29T21:36:59.813+0000] {standard_task_runner.py:85} INFO - Job 23: Subtask greet
[2023-06-29T21:36:59.844+0000] {task_command.py:410} INFO - Running <TaskInstance: dag_python_operador_03.greet manual__2023-06-29T21:36:58.120413+00:00 [running]> on host 3a20bfb037db
[2023-06-29T21:36:59.897+0000] {taskinstance.py:1547} INFO - Exporting env vars: AIRFLOW_CTX_DAG_OWNER='stare' AIRFLOW_CTX_DAG_ID='dag_python_operador_03' AIRFLOW_CTX_TASK_ID='greet' AIRFLOW_CTX_EXECUTION_DATE='2023-06-29T21:36:58.120413+00:00' AIRFLOW_CTX_TRY_NUMBER='1' AIRFLOW_CTX_DAG_RUN_ID='manual__2023-06-29T21:36:58.120413+00:00'
[2023-06-29T21:36:59.898+0000] {taskinstance.py:1824} ERROR - Task failed with exception
Traceback (most recent call last):
  File "/home/airflow/.local/lib/python3.7/site-packages/airflow/operators/python.py", line 181, in execute
    return_value = self.execute_callable()
  File "/home/airflow/.local/lib/python3.7/site-packages/airflow/operators/python.py", line 198, in execute_callable
    return self.python_callable(*self.op_args, **self.op_kwargs)
  File "/opt/airflow/dags/create_dag_with_python_operator.py", line 13, in greet
    name = ti.xcoms_pull(task_ids='get_name')
AttributeError: 'TaskInstance' object has no attribute 'xcoms_pull'
[2023-06-29T21:36:59.902+0000] {taskinstance.py:1350} INFO - Marking task as UP_FOR_RETRY. dag_id=dag_python_operador_03, task_id=greet, execution_date=20230629T213658, start_date=20230629T213659, end_date=20230629T213659
[2023-06-29T21:36:59.909+0000] {standard_task_runner.py:109} ERROR - Failed to execute job 23 for task greet ('TaskInstance' object has no attribute 'xcoms_pull'; 1860)
[2023-06-29T21:36:59.944+0000] {local_task_job_runner.py:225} INFO - Task exited with return code 1
[2023-06-29T21:36:59.956+0000] {taskinstance.py:2653} INFO - 0 downstream tasks scheduled from follow-on schedule check
